<?xml version="1.0" ?>
<!-- =================================================================================== -->
<!-- |    This document was autogenerated by xacro from kobuki_interbotix_astra.urdf.xacro | -->
<!-- |    EDITING THIS FILE BY HAND IS NOT RECOMMENDED                                 | -->
<!-- =================================================================================== -->
<!--
    - Base      : kobuki
    - Stacks    : interbotix
    - 3d Sensor : astra

    - arm : TODO: supported arms?
-->
<robot name="turtlebot" xmlns:xacro="http://ros.org/wiki/xacro">
  <!-- 
    These properties must be observed by any machine
    that wants to be defined as a turtlebot. Refer
    to the REP for more details.
    
    http://www.ros.org/reps/rep-0119.html
   -->
  <!-- TODO: Intertia fields do not contain valid data. Follow tutorial to correct them: http://gazebosim.org/tutorials?tut=inertia -->
  <!--TODO: Base link for turtlebot is 10.2mm from floor. Why? -->
  <gazebo>
    <plugin filename="libgazebo_ros_control.so" name="gazebo_ros_control">
      <robotNamespace>/turtlebot</robotNamespace>
      <robotSimType>gazebo_ros_control/DefaultRobotHWSim</robotSimType>
    </plugin>
  </gazebo>
  <!-- 
    These properties must be observed by any machine
    that wants to be defined as a turtlebot. Refer
    to the REP for more details.
    
    http://www.ros.org/reps/rep-0119.html
   -->
  <!--Sensor base is ~34.6mm below origin-->
  <gazebo>
    <plugin filename="libgazebo_ros_control.so" name="gazebo_ros_control">
      <robotNamespace>/turtlebot</robotNamespace>
      <robotSimType>gazebo_ros_control/DefaultRobotHWSim</robotSimType>
    </plugin>
  </gazebo>
  <!-- 
    These properties must be observed by any machine
    that wants to be defined as a turtlebot. Refer
    to the REP for more details.
    
    http://www.ros.org/reps/rep-0119.html
   -->
  <!--
  <xacro:property name="sr300_cam_rgb_px" value="0.005"/>
  <xacro:property name="sr300_cam_rgb_py" value="0.018"/>
  <xacro:property name="sr300_cam_rgb_pz" value="0.013"/>
  <xacro:property name="sr300_cam_depth_offset" value="0.01"/>
  -->
  <gazebo>
    <plugin filename="libgazebo_ros_control.so" name="gazebo_ros_control">
      <robotNamespace>/turtlebot</robotNamespace>
      <robotSimType>gazebo_ros_control/DefaultRobotHWSim</robotSimType>
    </plugin>
  </gazebo>
  <!-- 
    These properties must be observed by any machine
    that wants to be defined as a turtlebot. Refer
    to the REP for more details.
    
    http://www.ros.org/reps/rep-0119.html
   -->
  <link name="base_footprint"/>
  <!--
       Base link is set at the bottom of the base mould.
       This is done to be compatible with the way base link
       was configured for turtlebot 1. Refer to

       https://github.com/turtlebot/turtlebot/issues/40

       To put the base link at the more oft used wheel
       axis, set the z-distance from the base_footprint
       to 0.352.
      -->
  <joint name="base_joint" type="fixed">
    <origin rpy="0 0 0" xyz="0 0 0.0102"/>
    <parent link="base_footprint"/>
    <child link="base_link"/>
  </joint>
  <link name="base_link">
    <visual>
      <geometry>
        <!-- new mesh -->
        <mesh filename="package://kobuki_description/meshes/main_body.dae"/>
      </geometry>
      <origin rpy="0 0 0" xyz="0.001 0 0.05199"/>
    </visual>
    <collision name="base">
      <geometry>
        <cylinder length="0.10938" radius="0.178"/>
      </geometry>
      <origin rpy="0 0 0" xyz="0.0 0 0.05949"/>
    </collision>
    <inertial>
      <!-- COM experimentally determined -->
      <origin xyz="0.01 0 0"/>
      <mass value="2.4"/>
      <!-- 2.4/2.6 kg for small/big battery pack -->
      <!-- Kobuki's inertia tensor is approximated by a cylinder with homogeneous mass distribution
             More details: http://en.wikipedia.org/wiki/List_of_moment_of_inertia_tensors
             m = 2.4 kg; h = 0.09 m; r = 0.175 m
             ixx = 1/12 * m * (3 * r^2 + h^2)
             iyy = 1/12 * m * (3 * r^2 + h^2)
             izz = 1/2 * m * r^2
          -->
      <inertia ixx="0.019995" ixy="0.0" ixz="0.0" iyy="0.019995" iyz="0.0" izz="0.03675"/>
    </inertial>
  </link>
  <joint name="wheel_left_joint" type="continuous">
    <parent link="base_link"/>
    <child link="wheel_left_link"/>
    <origin rpy="-1.570795 0 0" xyz="0.00 0.115 0.0250"/>
    <axis xyz="0 0 1"/>
  </joint>
  <link name="wheel_left_link">
    <visual>
      <geometry>
        <mesh filename="package://kobuki_description/meshes/wheel.dae"/>
      </geometry>
      <origin rpy="0 0 0" xyz="0 0 0"/>
    </visual>
    <collision>
      <geometry>
        <cylinder length="0.0206" radius="0.0352"/>
      </geometry>
      <origin rpy="0 0 0" xyz="0 0 0"/>
    </collision>
    <inertial>
      <mass value="0.01"/>
      <origin xyz="0 0 0"/>
      <inertia ixx="0.001" ixy="0.0" ixz="0.0" iyy="0.001" iyz="0.0" izz="0.001"/>
    </inertial>
  </link>
  <joint name="wheel_right_joint" type="continuous">
    <parent link="base_link"/>
    <child link="wheel_right_link"/>
    <origin rpy="-1.570795 0 0" xyz="0.00 -0.115 0.0250"/>
    <axis xyz="0 0 1"/>
  </joint>
  <link name="wheel_right_link">
    <visual>
      <geometry>
        <mesh filename="package://kobuki_description/meshes/wheel.dae"/>
      </geometry>
      <origin rpy="0 0 0" xyz="0 0 0"/>
    </visual>
    <collision>
      <geometry>
        <cylinder length="0.0206" radius="0.0350"/>
      </geometry>
      <origin rpy="0 0 0" xyz="0 0 0"/>
    </collision>
    <inertial>
      <mass value="0.01"/>
      <origin xyz="0 0 0"/>
      <inertia ixx="0.001" ixy="0.0" ixz="0.0" iyy="0.001" iyz="0.0" izz="0.001"/>
    </inertial>
  </link>
  <joint name="caster_front_joint" type="fixed">
    <parent link="base_link"/>
    <child link="caster_front_link"/>
    <origin rpy="-1.570795 0 0" xyz="0.115 0.0 0.007"/>
  </joint>
  <link name="caster_front_link">
    <collision>
      <geometry>
        <cylinder length="0.0176" radius="0.017"/>
      </geometry>
      <origin rpy="0 0 0" xyz="0 0 0"/>
    </collision>
    <inertial>
      <mass value="0.01"/>
      <origin xyz="0 0 0"/>
      <inertia ixx="0.001" ixy="0.0" ixz="0.0" iyy="0.001" iyz="0.0" izz="0.001"/>
    </inertial>
  </link>
  <joint name="caster_back_joint" type="fixed">
    <parent link="base_link"/>
    <child link="caster_back_link"/>
    <origin rpy="-1.570795 0 0" xyz="-0.135 0.0 0.009"/>
  </joint>
  <link name="caster_back_link">
    <collision>
      <geometry>
        <cylinder length="0.0176" radius="0.017"/>
      </geometry>
      <origin rpy="0 0 0" xyz="0 0 0"/>
    </collision>
    <inertial>
      <mass value="0.01"/>
      <origin xyz="0 0 0"/>
      <inertia ixx="0.001" ixy="0.0" ixz="0.0" iyy="0.001" iyz="0.0" izz="0.001"/>
    </inertial>
  </link>
  <!-- Kobuki's sensors -->
  <joint name="gyro_joint" type="fixed">
    <axis xyz="0 1 0"/>
    <origin rpy="0 0 0" xyz="0.056 0.062 0.0202"/>
    <parent link="base_link"/>
    <child link="gyro_link"/>
  </joint>
  <link name="gyro_link">
    <inertial>
      <mass value="0.001"/>
      <origin rpy="0 0 0" xyz="0 0 0"/>
      <inertia ixx="0.0001" ixy="0" ixz="0" iyy="0.000001" iyz="0" izz="0.0001"/>
    </inertial>
  </link>
  <joint name="cliff_sensor_left_joint" type="fixed">
    <origin rpy="0 1.570795 0" xyz="0.08734 0.13601 0.0214"/>
    <parent link="base_link"/>
    <child link="cliff_sensor_left_link"/>
  </joint>
  <link name="cliff_sensor_left_link">
    <inertial>
      <mass value="0.0001"/>
      <origin xyz="0 0 0"/>
      <inertia ixx="0.0001" ixy="0.0" ixz="0.0" iyy="0.0001" iyz="0.0" izz="0.0001"/>
    </inertial>
  </link>
  <joint name="cliff_sensor_right_joint" type="fixed">
    <origin rpy="0 1.570795 0" xyz="0.085 -0.13601 0.0214"/>
    <parent link="base_link"/>
    <child link="cliff_sensor_right_link"/>
  </joint>
  <link name="cliff_sensor_right_link">
    <inertial>
      <mass value="0.0001"/>
      <origin xyz="0 0 0"/>
      <inertia ixx="0.0001" ixy="0.0" ixz="0.0" iyy="0.0001" iyz="0.0" izz="0.0001"/>
    </inertial>
  </link>
  <joint name="cliff_sensor_front_joint" type="fixed">
    <origin rpy="0 1.570795 0" xyz="0.156 0.00 0.0214"/>
    <parent link="base_link"/>
    <child link="cliff_sensor_front_link"/>
  </joint>
  <link name="cliff_sensor_front_link">
    <inertial>
      <mass value="0.0001"/>
      <origin xyz="0 0 0"/>
      <inertia ixx="0.0001" ixy="0.0" ixz="0.0" iyy="0.0001" iyz="0.0" izz="0.0001"/>
    </inertial>
  </link>
  <gazebo reference="wheel_left_link">
    <mu1>1.0</mu1>
    <mu2>1.0</mu2>
    <kp>1000000.0</kp>
    <kd>100.0</kd>
    <minDepth>0.001</minDepth>
    <maxVel>1.0</maxVel>
  </gazebo>
  <gazebo reference="wheel_right_link">
    <mu1>1.0</mu1>
    <mu2>1.0</mu2>
    <kp>1000000.0</kp>
    <kd>100.0</kd>
    <minDepth>0.001</minDepth>
    <maxVel>1.0</maxVel>
  </gazebo>
  <gazebo reference="caster_front_link">
    <mu1>0.0</mu1>
    <mu2>0.0</mu2>
    <kp>1000000.0</kp>
    <kd>100.0</kd>
    <minDepth>0.001</minDepth>
    <maxVel>1.0</maxVel>
  </gazebo>
  <gazebo reference="caster_back_link">
    <mu1>0.0</mu1>
    <mu2>0.0</mu2>
    <kp>1000000.0</kp>
    <kd>100.0</kd>
    <minDepth>0.001</minDepth>
    <maxVel>1.0</maxVel>
  </gazebo>
  <gazebo reference="base_link">
    <mu1>0.3</mu1>
    <mu2>0.3</mu2>
    <sensor name="bumpers" type="contact">
      <always_on>1</always_on>
      <update_rate>50.0</update_rate>
      <visualize>true</visualize>
      <contact>
        <collision>base_footprint_fixed_joint_lump__base_collision</collision>
      </contact>
    </sensor>
  </gazebo>
  <gazebo reference="cliff_sensor_left_link">
    <sensor name="cliff_sensor_left" type="ray">
      <always_on>true</always_on>
      <update_rate>50</update_rate>
      <visualize>true</visualize>
      <ray>
        <scan>
          <horizontal>
            <samples>50</samples>
            <resolution>1.0</resolution>
            <min_angle>-0.0436</min_angle>
            <!-- -2.5 degree -->
            <max_angle>0.0436</max_angle>
            <!-- 2.5 degree -->
          </horizontal>
          <!--            Can't use vertical rays until this bug is resolved: -->
          <!--            https://bitbucket.org/osrf/gazebo/issue/509/vertical-sensor-doesnt-works -->
          <!-- 	          <vertical> -->
          <!-- 	            <samples>50</samples> -->
          <!-- 	            <resolution>1.0</resolution> -->
          <!-- 	            <min_angle>-0.0436</min_angle>  -2.5 degree -->
          <!-- 	            <max_angle>0.0436</max_angle> 2.5 degree -->
          <!-- 	          </vertical> -->
        </scan>
        <range>
          <min>0.01</min>
          <max>0.15</max>
          <resolution>1.0</resolution>
        </range>
      </ray>
    </sensor>
  </gazebo>
  <gazebo reference="cliff_sensor_right_link">
    <sensor name="cliff_sensor_right" type="ray">
      <always_on>true</always_on>
      <update_rate>50</update_rate>
      <visualize>true</visualize>
      <ray>
        <scan>
          <horizontal>
            <samples>50</samples>
            <resolution>1.0</resolution>
            <min_angle>-0.0436</min_angle>
            <!-- -2.5 degree -->
            <max_angle>0.0436</max_angle>
            <!-- 2.5 degree -->
          </horizontal>
          <!--            Can't use vertical rays until this bug is resolved: -->
          <!--            https://bitbucket.org/osrf/gazebo/issue/509/vertical-sensor-doesnt-works -->
          <!-- 	          <vertical> -->
          <!-- 	            <samples>50</samples> -->
          <!-- 	            <resolution>1.0</resolution> -->
          <!-- 	            <min_angle>-0.0436</min_angle>  -2.5 degree -->
          <!-- 	            <max_angle>0.0436</max_angle> 2.5 degree -->
          <!-- 	          </vertical> -->
        </scan>
        <range>
          <min>0.01</min>
          <max>0.15</max>
          <resolution>1.0</resolution>
        </range>
      </ray>
    </sensor>
  </gazebo>
  <gazebo reference="cliff_sensor_front_link">
    <sensor name="cliff_sensor_front" type="ray">
      <always_on>true</always_on>
      <update_rate>50</update_rate>
      <visualize>true</visualize>
      <ray>
        <scan>
          <horizontal>
            <samples>50</samples>
            <resolution>1.0</resolution>
            <min_angle>-0.0436</min_angle>
            <!-- -2.5 degree -->
            <max_angle>0.0436</max_angle>
            <!-- 2.5 degree -->
          </horizontal>
          <!-- 	          Can't use vertical rays until this bug is resolved: -->
          <!--            https://bitbucket.org/osrf/gazebo/issue/509/vertical-sensor-doesnt-works -->
          <!-- 	          <vertical> -->
          <!-- 	            <samples>50</samples> -->
          <!-- 	            <resolution>1.0</resolution> -->
          <!-- 	            <min_angle>-0.0436</min_angle>  -2.5 degree -->
          <!-- 	            <max_angle>0.0436</max_angle> 2.5 degree -->
          <!-- 	          </vertical> -->
        </scan>
        <range>
          <min>0.01</min>
          <max>0.15</max>
          <resolution>1.0</resolution>
        </range>
      </ray>
    </sensor>
  </gazebo>
  <gazebo reference="gyro_link">
    <sensor name="imu" type="imu">
      <always_on>true</always_on>
      <update_rate>50</update_rate>
      <visualize>false</visualize>
      <imu>
        <noise>
          <type>gaussian</type>
          <rate>
            <mean>0.0</mean>
            <stddev>1.96e-06</stddev>
            <!-- 0.25 x 0.25 (deg/s) -->
            <bias_mean>0.0</bias_mean>
            <bias_stddev>0.0</bias_stddev>
          </rate>
          <accel>
            <!-- not used in the plugin and real robot, hence using tutorial values -->
            <mean>0.0</mean>
            <stddev>1.7e-2</stddev>
            <bias_mean>0.1</bias_mean>
            <bias_stddev>0.001</bias_stddev>
          </accel>
        </noise>
      </imu>
    </sensor>
  </gazebo>
  <gazebo>
    <plugin filename="libgazebo_ros_kobuki.so" name="kobuki_controller">
      <publish_tf>1</publish_tf>
      <left_wheel_joint_name>wheel_left_joint</left_wheel_joint_name>
      <right_wheel_joint_name>wheel_right_joint</right_wheel_joint_name>
      <wheel_separation>.230</wheel_separation>
      <wheel_diameter>0.070</wheel_diameter>
      <torque>1.0</torque>
      <velocity_command_timeout>0.6</velocity_command_timeout>
      <cliff_sensor_left_name>cliff_sensor_left</cliff_sensor_left_name>
      <cliff_sensor_center_name>cliff_sensor_front</cliff_sensor_center_name>
      <cliff_sensor_right_name>cliff_sensor_right</cliff_sensor_right_name>
      <cliff_detection_threshold>0.04</cliff_detection_threshold>
      <bumper_name>bumpers</bumper_name>
      <imu_name>imu</imu_name>
    </plugin>
  </gazebo>
  <joint name="standoff_38mm_0_joint" type="fixed">
    <origin rpy="0 0 0" xyz="0.12 0.082 0.1063"/>
    <parent link="base_link"/>
    <child link="standoff_38mm_0_link"/>
  </joint>
  <link name="standoff_38mm_0_link">
    <visual>
      <origin rpy="0 0 0" xyz="0 0 0"/>
      <geometry>
        <mesh filename="package://turtlebot2i_description/meshes/stacks/interbotix/38mm_HexStandoff_MF.stl"/>
      </geometry>
      <material name="pink">
        <color rgba="0.8 0.0 0.4 1"/>
      </material>
    </visual>
    <collision>
      <origin rpy="0 0 0" xyz="0 0 0"/>
      <geometry>
        <cylinder length="0.038" radius="0.006"/>
      </geometry>
    </collision>
    <inertial>
      <mass value="0.008"/>
      <origin rpy="0 0 0" xyz="0 0 0"/>
      <inertia ixx="0.000001686" ixy="0.0" ixz="0.0" iyy="0.000001686" iyz="0.0" izz="0.000000144"/>
    </inertial>
  </link>
  <gazebo reference="standoff_38mm_0_link">
    <material>Gazebo/Black</material>
    <selfCollide>true</selfCollide>
    <gravity>true</gravity>
  </gazebo>
  <joint name="standoff_38mm_1_joint" type="fixed">
    <origin rpy="0 0 0" xyz="0.055 0.12 0.1063"/>
    <parent link="base_link"/>
    <child link="standoff_38mm_1_link"/>
  </joint>
  <link name="standoff_38mm_1_link">
    <visual>
      <origin rpy="0 0 0" xyz="0 0 0"/>
      <geometry>
        <mesh filename="package://turtlebot2i_description/meshes/stacks/interbotix/38mm_HexStandoff_MF.stl"/>
      </geometry>
      <material name="pink">
        <color rgba="0.8 0.0 0.4 1"/>
      </material>
    </visual>
    <collision>
      <origin rpy="0 0 0" xyz="0 0 0"/>
      <geometry>
        <cylinder length="0.038" radius="0.006"/>
      </geometry>
    </collision>
    <inertial>
      <mass value="0.008"/>
      <origin rpy="0 0 0" xyz="0 0 0"/>
      <inertia ixx="0.000001686" ixy="0.0" ixz="0.0" iyy="0.000001686" iyz="0.0" izz="0.000000144"/>
    </inertial>
  </link>
  <gazebo reference="standoff_38mm_1_link">
    <material>Gazebo/Black</material>
    <selfCollide>true</selfCollide>
    <gravity>true</gravity>
  </gazebo>
  <joint name="standoff_38mm_2_joint" type="fixed">
    <origin rpy="0 0 0" xyz="-0.055 0.12 0.1063"/>
    <parent link="base_link"/>
    <child link="standoff_38mm_2_link"/>
  </joint>
  <link name="standoff_38mm_2_link">
    <visual>
      <origin rpy="0 0 0" xyz="0 0 0"/>
      <geometry>
        <mesh filename="package://turtlebot2i_description/meshes/stacks/interbotix/38mm_HexStandoff_MF.stl"/>
      </geometry>
      <material name="pink">
        <color rgba="0.8 0.0 0.4 1"/>
      </material>
    </visual>
    <collision>
      <origin rpy="0 0 0" xyz="0 0 0"/>
      <geometry>
        <cylinder length="0.038" radius="0.006"/>
      </geometry>
    </collision>
    <inertial>
      <mass value="0.008"/>
      <origin rpy="0 0 0" xyz="0 0 0"/>
      <inertia ixx="0.000001686" ixy="0.0" ixz="0.0" iyy="0.000001686" iyz="0.0" izz="0.000000144"/>
    </inertial>
  </link>
  <gazebo reference="standoff_38mm_2_link">
    <material>Gazebo/Black</material>
    <selfCollide>true</selfCollide>
    <gravity>true</gravity>
  </gazebo>
  <joint name="standoff_38mm_3_joint" type="fixed">
    <origin rpy="0 0 0" xyz="0.12 -0.082 0.1063"/>
    <parent link="base_link"/>
    <child link="standoff_38mm_3_link"/>
  </joint>
  <link name="standoff_38mm_3_link">
    <visual>
      <origin rpy="0 0 0" xyz="0 0 0"/>
      <geometry>
        <mesh filename="package://turtlebot2i_description/meshes/stacks/interbotix/38mm_HexStandoff_MF.stl"/>
      </geometry>
      <material name="pink">
        <color rgba="0.8 0.0 0.4 1"/>
      </material>
    </visual>
    <collision>
      <origin rpy="0 0 0" xyz="0 0 0"/>
      <geometry>
        <cylinder length="0.038" radius="0.006"/>
      </geometry>
    </collision>
    <inertial>
      <mass value="0.008"/>
      <origin rpy="0 0 0" xyz="0 0 0"/>
      <inertia ixx="0.000001686" ixy="0.0" ixz="0.0" iyy="0.000001686" iyz="0.0" izz="0.000000144"/>
    </inertial>
  </link>
  <gazebo reference="standoff_38mm_3_link">
    <material>Gazebo/Black</material>
    <selfCollide>true</selfCollide>
    <gravity>true</gravity>
  </gazebo>
  <joint name="standoff_38mm_4_joint" type="fixed">
    <origin rpy="0 0 0" xyz="0.055 -0.12 0.1063"/>
    <parent link="base_link"/>
    <child link="standoff_38mm_4_link"/>
  </joint>
  <link name="standoff_38mm_4_link">
    <visual>
      <origin rpy="0 0 0" xyz="0 0 0"/>
      <geometry>
        <mesh filename="package://turtlebot2i_description/meshes/stacks/interbotix/38mm_HexStandoff_MF.stl"/>
      </geometry>
      <material name="pink">
        <color rgba="0.8 0.0 0.4 1"/>
      </material>
    </visual>
    <collision>
      <origin rpy="0 0 0" xyz="0 0 0"/>
      <geometry>
        <cylinder length="0.038" radius="0.006"/>
      </geometry>
    </collision>
    <inertial>
      <mass value="0.008"/>
      <origin rpy="0 0 0" xyz="0 0 0"/>
      <inertia ixx="0.000001686" ixy="0.0" ixz="0.0" iyy="0.000001686" iyz="0.0" izz="0.000000144"/>
    </inertial>
  </link>
  <gazebo reference="standoff_38mm_4_link">
    <material>Gazebo/Black</material>
    <selfCollide>true</selfCollide>
    <gravity>true</gravity>
  </gazebo>
  <joint name="standoff_38mm_5_joint" type="fixed">
    <origin rpy="0 0 0" xyz="-0.055 -0.12 0.1063"/>
    <parent link="base_link"/>
    <child link="standoff_38mm_5_link"/>
  </joint>
  <link name="standoff_38mm_5_link">
    <visual>
      <origin rpy="0 0 0" xyz="0 0 0"/>
      <geometry>
        <mesh filename="package://turtlebot2i_description/meshes/stacks/interbotix/38mm_HexStandoff_MF.stl"/>
      </geometry>
      <material name="pink">
        <color rgba="0.8 0.0 0.4 1"/>
      </material>
    </visual>
    <collision>
      <origin rpy="0 0 0" xyz="0 0 0"/>
      <geometry>
        <cylinder length="0.038" radius="0.006"/>
      </geometry>
    </collision>
    <inertial>
      <mass value="0.008"/>
      <origin rpy="0 0 0" xyz="0 0 0"/>
      <inertia ixx="0.000001686" ixy="0.0" ixz="0.0" iyy="0.000001686" iyz="0.0" izz="0.000000144"/>
    </inertial>
  </link>
  <gazebo reference="standoff_38mm_5_link">
    <material>Gazebo/Black</material>
    <selfCollide>true</selfCollide>
    <gravity>true</gravity>
  </gazebo>
  <joint name="plate_bottom_joint" type="fixed">
    <origin rpy="0 0 0" xyz="0.0 0.0 0.1276"/>
    <parent link="base_link"/>
    <child link="plate_bottom_link"/>
  </joint>
  <link name="plate_bottom_link">
    <visual>
      <origin rpy="0 0 0" xyz="0 0 0"/>
      <geometry>
        <mesh filename="package://turtlebot2i_description/meshes/stacks/interbotix/TurtleBot2i_BottomPlate.stl"/>
      </geometry>
      <material name="near_black">
        <color rgba="0.125 0.125 0.125 1"/>
      </material>
    </visual>
    <collision>
      <origin rpy="0 0 0" xyz="0 0 0"/>
      <geometry>
        <cylinder length="0.006" radius="0.170"/>
      </geometry>
    </collision>
    <inertial>
      <mass value="0.311"/>
      <origin xyz="0 0 0"/>
      <inertia ixx="0.003328" ixy="0.0" ixz="0.0" iyy="0.003328" iyz="0.0" izz="0.006656"/>
    </inertial>
  </link>
  <gazebo reference="plate_bottom_link">
    <material>Gazebo/Black</material>
    <selfCollide>true</selfCollide>
    <gravity>true</gravity>
  </gazebo>
  <joint name="standoff_51mm_0_joint" type="fixed">
    <origin rpy="0 0 0" xyz="0.069 0.13 0.1554"/>
    <parent link="base_link"/>
    <child link="standoff_51mm_0_link"/>
  </joint>
  <link name="standoff_51mm_0_link">
    <visual>
      <origin rpy="0 3.14159 0" xyz="0 0 0"/>
      <geometry>
        <mesh filename="package://turtlebot2i_description/meshes/stacks/interbotix/51mm_HexStandoff_FF.stl"/>
      </geometry>
      <material name="pink">
        <color rgba="0.8 0.0 0.4 1"/>
      </material>
    </visual>
    <collision>
      <origin rpy="0 0 0" xyz="0 0 0"/>
      <geometry>
        <cylinder length="0.051" radius="0.006"/>
      </geometry>
    </collision>
    <inertial>
      <mass value="0.012"/>
      <origin xyz="0 0 0"/>
      <inertia ixx="0.000003805" ixy="0.0" ixz="0.0" iyy="0.000003805" iyz="0.0" izz="0.000000216"/>
    </inertial>
  </link>
  <gazebo reference="standoff_51mm_0_link">
    <material>Gazebo/Black</material>
    <selfCollide>true</selfCollide>
    <gravity>true</gravity>
  </gazebo>
  <joint name="standoff_51mm_1_joint" type="fixed">
    <origin rpy="0 0 0" xyz="0.069 -0.13 0.1554"/>
    <parent link="base_link"/>
    <child link="standoff_51mm_1_link"/>
  </joint>
  <link name="standoff_51mm_1_link">
    <visual>
      <origin rpy="0 3.14159 0" xyz="0 0 0"/>
      <geometry>
        <mesh filename="package://turtlebot2i_description/meshes/stacks/interbotix/51mm_HexStandoff_FF.stl"/>
      </geometry>
      <material name="pink">
        <color rgba="0.8 0.0 0.4 1"/>
      </material>
    </visual>
    <collision>
      <origin rpy="0 0 0" xyz="0 0 0"/>
      <geometry>
        <cylinder length="0.051" radius="0.006"/>
      </geometry>
    </collision>
    <inertial>
      <mass value="0.012"/>
      <origin xyz="0 0 0"/>
      <inertia ixx="0.000003805" ixy="0.0" ixz="0.0" iyy="0.000003805" iyz="0.0" izz="0.000000216"/>
    </inertial>
  </link>
  <gazebo reference="standoff_51mm_1_link">
    <material>Gazebo/Black</material>
    <selfCollide>true</selfCollide>
    <gravity>true</gravity>
  </gazebo>
  <joint name="standoff_51mm_2_joint" type="fixed">
    <origin rpy="0 0 0" xyz="-0.001 0.162 0.1554"/>
    <parent link="base_link"/>
    <child link="standoff_51mm_2_link"/>
  </joint>
  <link name="standoff_51mm_2_link">
    <visual>
      <origin rpy="0 3.14159 0" xyz="0 0 0"/>
      <geometry>
        <mesh filename="package://turtlebot2i_description/meshes/stacks/interbotix/51mm_HexStandoff_FF.stl"/>
      </geometry>
      <material name="pink">
        <color rgba="0.8 0.0 0.4 1"/>
      </material>
    </visual>
    <collision>
      <origin rpy="0 0 0" xyz="0 0 0"/>
      <geometry>
        <cylinder length="0.051" radius="0.006"/>
      </geometry>
    </collision>
    <inertial>
      <mass value="0.012"/>
      <origin xyz="0 0 0"/>
      <inertia ixx="0.000003805" ixy="0.0" ixz="0.0" iyy="0.000003805" iyz="0.0" izz="0.000000216"/>
    </inertial>
  </link>
  <gazebo reference="standoff_51mm_2_link">
    <material>Gazebo/Black</material>
    <selfCollide>true</selfCollide>
    <gravity>true</gravity>
  </gazebo>
  <joint name="standoff_51mm_3_joint" type="fixed">
    <origin rpy="0 0 0" xyz="-0.001 -0.162 0.1554"/>
    <parent link="base_link"/>
    <child link="standoff_51mm_3_link"/>
  </joint>
  <link name="standoff_51mm_3_link">
    <visual>
      <origin rpy="0 3.14159 0" xyz="0 0 0"/>
      <geometry>
        <mesh filename="package://turtlebot2i_description/meshes/stacks/interbotix/51mm_HexStandoff_FF.stl"/>
      </geometry>
      <material name="pink">
        <color rgba="0.8 0.0 0.4 1"/>
      </material>
    </visual>
    <collision>
      <origin rpy="0 0 0" xyz="0 0 0"/>
      <geometry>
        <cylinder length="0.051" radius="0.006"/>
      </geometry>
    </collision>
    <inertial>
      <mass value="0.012"/>
      <origin xyz="0 0 0"/>
      <inertia ixx="0.000003805" ixy="0.0" ixz="0.0" iyy="0.000003805" iyz="0.0" izz="0.000000216"/>
    </inertial>
  </link>
  <gazebo reference="standoff_51mm_3_link">
    <material>Gazebo/Black</material>
    <selfCollide>true</selfCollide>
    <gravity>true</gravity>
  </gazebo>
  <joint name="standoff_51mm_4_joint" type="fixed">
    <origin rpy="0 0 0" xyz="-0.104 0.098 0.1554"/>
    <parent link="base_link"/>
    <child link="standoff_51mm_4_link"/>
  </joint>
  <link name="standoff_51mm_4_link">
    <visual>
      <origin rpy="0 3.14159 0" xyz="0 0 0"/>
      <geometry>
        <mesh filename="package://turtlebot2i_description/meshes/stacks/interbotix/51mm_HexStandoff_FF.stl"/>
      </geometry>
      <material name="pink">
        <color rgba="0.8 0.0 0.4 1"/>
      </material>
    </visual>
    <collision>
      <origin rpy="0 0 0" xyz="0 0 0"/>
      <geometry>
        <cylinder length="0.051" radius="0.006"/>
      </geometry>
    </collision>
    <inertial>
      <mass value="0.012"/>
      <origin xyz="0 0 0"/>
      <inertia ixx="0.000003805" ixy="0.0" ixz="0.0" iyy="0.000003805" iyz="0.0" izz="0.000000216"/>
    </inertial>
  </link>
  <gazebo reference="standoff_51mm_4_link">
    <material>Gazebo/Black</material>
    <selfCollide>true</selfCollide>
    <gravity>true</gravity>
  </gazebo>
  <joint name="standoff_51mm_5_joint" type="fixed">
    <origin rpy="0 0 0" xyz="-0.104 -0.098 0.1554"/>
    <parent link="base_link"/>
    <child link="standoff_51mm_5_link"/>
  </joint>
  <link name="standoff_51mm_5_link">
    <visual>
      <origin rpy="0 3.14159 0" xyz="0 0 0"/>
      <geometry>
        <mesh filename="package://turtlebot2i_description/meshes/stacks/interbotix/51mm_HexStandoff_FF.stl"/>
      </geometry>
      <material name="pink">
        <color rgba="0.8 0.0 0.4 1"/>
      </material>
    </visual>
    <collision>
      <origin rpy="0 0 0" xyz="0 0 0"/>
      <geometry>
        <cylinder length="0.051" radius="0.006"/>
      </geometry>
    </collision>
    <inertial>
      <mass value="0.012"/>
      <origin xyz="0 0 0"/>
      <inertia ixx="0.000003805" ixy="0.0" ixz="0.0" iyy="0.000003805" iyz="0.0" izz="0.000000216"/>
    </inertial>
  </link>
  <gazebo reference="standoff_51mm_5_link">
    <material>Gazebo/Black</material>
    <selfCollide>true</selfCollide>
    <gravity>true</gravity>
  </gazebo>
  <joint name="plate_middle_joint" type="fixed">
    <origin rpy="0 0 0" xyz="0.0 0.0 0.1832"/>
    <parent link="base_link"/>
    <child link="plate_middle_link"/>
  </joint>
  <link name="plate_middle_link">
    <visual>
      <origin rpy="0 0 0" xyz="0 0 0"/>
      <geometry>
        <mesh filename="package://turtlebot2i_description/meshes/stacks/interbotix/TurtleBot2i_MiddlePlate.stl"/>
      </geometry>
      <material name="near_black">
        <color rgba="0.125 0.125 0.125 1"/>
      </material>
    </visual>
    <collision>
      <origin rpy="0 0 0" xyz="0.0 0.0 0.0"/>
      <geometry>
        <mesh filename="package://turtlebot2i_description/meshes/stacks/interbotix/TurtleBot2i_MiddlePlate.stl"/>
      </geometry>
    </collision>
    <inertial>
      <mass value="0.299"/>
      <origin xyz="0 0 0"/>
      <inertia ixx="0.003328" ixy="0.0" ixz="0.0" iyy="0.003328" iyz="0.0" izz="0.006656"/>
    </inertial>
  </link>
  <gazebo reference="plate_middle_link">
    <material>Gazebo/Black</material>
    <selfCollide>true</selfCollide>
    <gravity>true</gravity>
  </gazebo>
  <joint name="standoff_81mm_6_joint" type="fixed">
    <origin rpy="0 0 0" xyz="-0.001 0.162 0.2258"/>
    <parent link="base_link"/>
    <child link="standoff_81mm_6_link"/>
  </joint>
  <link name="standoff_81mm_6_link">
    <visual>
      <origin rpy="0 0 0" xyz=" 0 0 0"/>
      <geometry>
        <mesh filename="package://turtlebot2i_description/meshes/stacks/interbotix/81mm_Spacer.stl"/>
      </geometry>
      <material name="pink">
        <color rgba="0.8 0.0 0.4 1"/>
      </material>
    </visual>
    <collision>
      <origin rpy="0 0 0" xyz="0 0 0"/>
      <geometry>
        <cylinder length="0.0806" radius="0.012"/>
      </geometry>
    </collision>
    <inertial>
      <mass value="0.060"/>
      <origin xyz="0 0 0"/>
      <inertia ixx="0.000206991" ixy="0.0" ixz="0.0" iyy="0.000206991" iyz="0.0" izz="0.000001080"/>
    </inertial>
  </link>
  <gazebo reference="standoff_81mm_6_link">
    <material>Gazebo/Black</material>
    <selfCollide>true</selfCollide>
    <gravity>true</gravity>
  </gazebo>
  <joint name="standoff_81mm_7_joint" type="fixed">
    <origin rpy="0 0 0" xyz="-0.001 -0.162 0.2258"/>
    <parent link="base_link"/>
    <child link="standoff_81mm_7_link"/>
  </joint>
  <link name="standoff_81mm_7_link">
    <visual>
      <origin rpy="0 0 0" xyz=" 0 0 0"/>
      <geometry>
        <mesh filename="package://turtlebot2i_description/meshes/stacks/interbotix/81mm_Spacer.stl"/>
      </geometry>
      <material name="pink">
        <color rgba="0.8 0.0 0.4 1"/>
      </material>
    </visual>
    <collision>
      <origin rpy="0 0 0" xyz="0 0 0"/>
      <geometry>
        <cylinder length="0.0806" radius="0.012"/>
      </geometry>
    </collision>
    <inertial>
      <mass value="0.060"/>
      <origin xyz="0 0 0"/>
      <inertia ixx="0.000206991" ixy="0.0" ixz="0.0" iyy="0.000206991" iyz="0.0" izz="0.000001080"/>
    </inertial>
  </link>
  <gazebo reference="standoff_81mm_7_link">
    <material>Gazebo/Black</material>
    <selfCollide>true</selfCollide>
    <gravity>true</gravity>
  </gazebo>
  <joint name="standoff_81mm_8_joint" type="fixed">
    <origin rpy="0 0 0" xyz="-0.104 0.098 0.2258"/>
    <parent link="base_link"/>
    <child link="standoff_81mm_8_link"/>
  </joint>
  <link name="standoff_81mm_8_link">
    <visual>
      <origin rpy="0 0 0" xyz=" 0 0 0"/>
      <geometry>
        <mesh filename="package://turtlebot2i_description/meshes/stacks/interbotix/81mm_Spacer.stl"/>
      </geometry>
      <material name="pink">
        <color rgba="0.8 0.0 0.4 1"/>
      </material>
    </visual>
    <collision>
      <origin rpy="0 0 0" xyz="0 0 0"/>
      <geometry>
        <cylinder length="0.0806" radius="0.012"/>
      </geometry>
    </collision>
    <inertial>
      <mass value="0.060"/>
      <origin xyz="0 0 0"/>
      <inertia ixx="0.000206991" ixy="0.0" ixz="0.0" iyy="0.000206991" iyz="0.0" izz="0.000001080"/>
    </inertial>
  </link>
  <gazebo reference="standoff_81mm_8_link">
    <material>Gazebo/Black</material>
    <selfCollide>true</selfCollide>
    <gravity>true</gravity>
  </gazebo>
  <joint name="standoff_81mm_9_joint" type="fixed">
    <origin rpy="0 0 0" xyz="-0.104 -0.098 0.2258"/>
    <parent link="base_link"/>
    <child link="standoff_81mm_9_link"/>
  </joint>
  <link name="standoff_81mm_9_link">
    <visual>
      <origin rpy="0 0 0" xyz=" 0 0 0"/>
      <geometry>
        <mesh filename="package://turtlebot2i_description/meshes/stacks/interbotix/81mm_Spacer.stl"/>
      </geometry>
      <material name="pink">
        <color rgba="0.8 0.0 0.4 1"/>
      </material>
    </visual>
    <collision>
      <origin rpy="0 0 0" xyz="0 0 0"/>
      <geometry>
        <cylinder length="0.0806" radius="0.012"/>
      </geometry>
    </collision>
    <inertial>
      <mass value="0.060"/>
      <origin xyz="0 0 0"/>
      <inertia ixx="0.000206991" ixy="0.0" ixz="0.0" iyy="0.000206991" iyz="0.0" izz="0.000001080"/>
    </inertial>
  </link>
  <gazebo reference="standoff_81mm_9_link">
    <material>Gazebo/Black</material>
    <selfCollide>true</selfCollide>
    <gravity>true</gravity>
  </gazebo>
  <joint name="plate_utility_lower" type="fixed">
    <origin rpy="0 0 0" xyz="0.0 0.0 0.2684"/>
    <parent link="base_link"/>
    <child link="plate_utility_lower_link"/>
  </joint>
  <link name="plate_utility_lower_link">
    <visual>
      <origin rpy="0 0 0" xyz="0 0 0"/>
      <geometry>
        <mesh filename="package://turtlebot2i_description/meshes/stacks/interbotix/TurtleBot2i_CameraPlate.stl"/>
      </geometry>
      <material name="near_black">
        <color rgba="0.125 0.125 0.125 1"/>
      </material>
    </visual>
    <collision>
      <origin rpy="0 0 0" xyz="0.0 0.0 0.0"/>
      <geometry>
        <mesh filename="package://turtlebot2i_description/meshes/stacks/interbotix/TurtleBot2i_CameraPlate.stl"/>
      </geometry>
    </collision>
    <inertial>
      <mass value="0.151"/>
      <origin xyz="0 0 0"/>
      <inertia ixx="0.003328" ixy="0.0" ixz="0.0" iyy="0.003328" iyz="0.0" izz="0.006656"/>
    </inertial>
  </link>
  <gazebo reference="plate_utility_lower_link">
    <material>Gazebo/Black</material>
    <selfCollide>true</selfCollide>
    <gravity>true</gravity>
  </gazebo>
  <joint name="standoff_81mm_0_joint" type="fixed">
    <origin rpy="0 0 0" xyz="-0.001 0.162 0.311"/>
    <parent link="base_link"/>
    <child link="standoff_81mm_0_link"/>
  </joint>
  <link name="standoff_81mm_0_link">
    <visual>
      <origin rpy="0 0 0" xyz=" 0 0 0"/>
      <geometry>
        <mesh filename="package://turtlebot2i_description/meshes/stacks/interbotix/81mm_Spacer.stl"/>
      </geometry>
      <material name="pink">
        <color rgba="0.8 0.0 0.4 1"/>
      </material>
    </visual>
    <collision>
      <origin rpy="0 0 0" xyz="0 0 0"/>
      <geometry>
        <cylinder length="0.0806" radius="0.012"/>
      </geometry>
    </collision>
    <inertial>
      <mass value="0.060"/>
      <origin xyz="0 0 0"/>
      <inertia ixx="0.000206991" ixy="0.0" ixz="0.0" iyy="0.000206991" iyz="0.0" izz="0.000001080"/>
    </inertial>
  </link>
  <gazebo reference="standoff_81mm_0_link">
    <material>Gazebo/Black</material>
    <selfCollide>true</selfCollide>
    <gravity>true</gravity>
  </gazebo>
  <joint name="standoff_81mm_1_joint" type="fixed">
    <origin rpy="0 0 0" xyz="-0.001 -0.162 0.311"/>
    <parent link="base_link"/>
    <child link="standoff_81mm_1_link"/>
  </joint>
  <link name="standoff_81mm_1_link">
    <visual>
      <origin rpy="0 0 0" xyz=" 0 0 0"/>
      <geometry>
        <mesh filename="package://turtlebot2i_description/meshes/stacks/interbotix/81mm_Spacer.stl"/>
      </geometry>
      <material name="pink">
        <color rgba="0.8 0.0 0.4 1"/>
      </material>
    </visual>
    <collision>
      <origin rpy="0 0 0" xyz="0 0 0"/>
      <geometry>
        <cylinder length="0.0806" radius="0.012"/>
      </geometry>
    </collision>
    <inertial>
      <mass value="0.060"/>
      <origin xyz="0 0 0"/>
      <inertia ixx="0.000206991" ixy="0.0" ixz="0.0" iyy="0.000206991" iyz="0.0" izz="0.000001080"/>
    </inertial>
  </link>
  <gazebo reference="standoff_81mm_1_link">
    <material>Gazebo/Black</material>
    <selfCollide>true</selfCollide>
    <gravity>true</gravity>
  </gazebo>
  <joint name="standoff_81mm_2_joint" type="fixed">
    <origin rpy="0 0 0" xyz="-0.104 0.098 0.311"/>
    <parent link="base_link"/>
    <child link="standoff_81mm_2_link"/>
  </joint>
  <link name="standoff_81mm_2_link">
    <visual>
      <origin rpy="0 0 0" xyz=" 0 0 0"/>
      <geometry>
        <mesh filename="package://turtlebot2i_description/meshes/stacks/interbotix/81mm_Spacer.stl"/>
      </geometry>
      <material name="pink">
        <color rgba="0.8 0.0 0.4 1"/>
      </material>
    </visual>
    <collision>
      <origin rpy="0 0 0" xyz="0 0 0"/>
      <geometry>
        <cylinder length="0.0806" radius="0.012"/>
      </geometry>
    </collision>
    <inertial>
      <mass value="0.060"/>
      <origin xyz="0 0 0"/>
      <inertia ixx="0.000206991" ixy="0.0" ixz="0.0" iyy="0.000206991" iyz="0.0" izz="0.000001080"/>
    </inertial>
  </link>
  <gazebo reference="standoff_81mm_2_link">
    <material>Gazebo/Black</material>
    <selfCollide>true</selfCollide>
    <gravity>true</gravity>
  </gazebo>
  <joint name="standoff_81mm_3_joint" type="fixed">
    <origin rpy="0 0 0" xyz="-0.104 -0.098 0.311"/>
    <parent link="base_link"/>
    <child link="standoff_81mm_3_link"/>
  </joint>
  <link name="standoff_81mm_3_link">
    <visual>
      <origin rpy="0 0 0" xyz=" 0 0 0"/>
      <geometry>
        <mesh filename="package://turtlebot2i_description/meshes/stacks/interbotix/81mm_Spacer.stl"/>
      </geometry>
      <material name="pink">
        <color rgba="0.8 0.0 0.4 1"/>
      </material>
    </visual>
    <collision>
      <origin rpy="0 0 0" xyz="0 0 0"/>
      <geometry>
        <cylinder length="0.0806" radius="0.012"/>
      </geometry>
    </collision>
    <inertial>
      <mass value="0.060"/>
      <origin xyz="0 0 0"/>
      <inertia ixx="0.000206991" ixy="0.0" ixz="0.0" iyy="0.000206991" iyz="0.0" izz="0.000001080"/>
    </inertial>
  </link>
  <gazebo reference="standoff_81mm_3_link">
    <material>Gazebo/Black</material>
    <selfCollide>true</selfCollide>
    <gravity>true</gravity>
  </gazebo>
  <joint name="plate_utility_upper" type="fixed">
    <origin rpy="0 0 0" xyz="0.0 0.0 0.3536"/>
    <parent link="base_link"/>
    <child link="plate_utility_upper_link"/>
  </joint>
  <link name="plate_utility_upper_link">
    <visual>
      <origin rpy="0 0 0" xyz="0 0 0"/>
      <geometry>
        <mesh filename="package://turtlebot2i_description/meshes/stacks/interbotix/TurtleBot2i_UtilityPlate.stl"/>
      </geometry>
      <material name="near_black">
        <color rgba="0.125 0.125 0.125 1"/>
      </material>
    </visual>
    <collision>
      <origin rpy="0 0 0" xyz="0.0 0.0 0.0"/>
      <geometry>
        <mesh filename="package://turtlebot2i_description/meshes/stacks/interbotix/TurtleBot2i_UtilityPlate.stl"/>
      </geometry>
    </collision>
    <inertial>
      <mass value="0.153"/>
      <origin xyz="0 0 0"/>
      <inertia ixx="0.003328" ixy="0.0" ixz="0.0" iyy="0.003328" iyz="0.0" izz="0.006656"/>
    </inertial>
  </link>
  <gazebo reference="plate_utility_upper_link">
    <material>Gazebo/Black</material>
    <selfCollide>true</selfCollide>
    <gravity>true</gravity>
  </gazebo>
  <joint name="standoff_81mm_10_joint" type="fixed">
    <origin rpy="0 0 0" xyz="-0.001 0.162 0.3962"/>
    <parent link="base_link"/>
    <child link="standoff_81mm_10_link"/>
  </joint>
  <link name="standoff_81mm_10_link">
    <visual>
      <origin rpy="0 0 0" xyz=" 0 0 0"/>
      <geometry>
        <mesh filename="package://turtlebot2i_description/meshes/stacks/interbotix/81mm_Spacer.stl"/>
      </geometry>
      <material name="pink">
        <color rgba="0.8 0.0 0.4 1"/>
      </material>
    </visual>
    <collision>
      <origin rpy="0 0 0" xyz="0 0 0"/>
      <geometry>
        <cylinder length="0.0806" radius="0.012"/>
      </geometry>
    </collision>
    <inertial>
      <mass value="0.060"/>
      <origin xyz="0 0 0"/>
      <inertia ixx="0.000206991" ixy="0.0" ixz="0.0" iyy="0.000206991" iyz="0.0" izz="0.000001080"/>
    </inertial>
  </link>
  <gazebo reference="standoff_81mm_10_link">
    <material>Gazebo/Black</material>
    <selfCollide>true</selfCollide>
    <gravity>true</gravity>
  </gazebo>
  <joint name="standoff_81mm_11_joint" type="fixed">
    <origin rpy="0 0 0" xyz="-0.001 -0.162 0.3962"/>
    <parent link="base_link"/>
    <child link="standoff_81mm_11_link"/>
  </joint>
  <link name="standoff_81mm_11_link">
    <visual>
      <origin rpy="0 0 0" xyz=" 0 0 0"/>
      <geometry>
        <mesh filename="package://turtlebot2i_description/meshes/stacks/interbotix/81mm_Spacer.stl"/>
      </geometry>
      <material name="pink">
        <color rgba="0.8 0.0 0.4 1"/>
      </material>
    </visual>
    <collision>
      <origin rpy="0 0 0" xyz="0 0 0"/>
      <geometry>
        <cylinder length="0.0806" radius="0.012"/>
      </geometry>
    </collision>
    <inertial>
      <mass value="0.060"/>
      <origin xyz="0 0 0"/>
      <inertia ixx="0.000206991" ixy="0.0" ixz="0.0" iyy="0.000206991" iyz="0.0" izz="0.000001080"/>
    </inertial>
  </link>
  <gazebo reference="standoff_81mm_11_link">
    <material>Gazebo/Black</material>
    <selfCollide>true</selfCollide>
    <gravity>true</gravity>
  </gazebo>
  <joint name="standoff_81mm_12_joint" type="fixed">
    <origin rpy="0 0 0" xyz="-0.104 0.098 0.3962"/>
    <parent link="base_link"/>
    <child link="standoff_81mm_12_link"/>
  </joint>
  <link name="standoff_81mm_12_link">
    <visual>
      <origin rpy="0 0 0" xyz=" 0 0 0"/>
      <geometry>
        <mesh filename="package://turtlebot2i_description/meshes/stacks/interbotix/81mm_Spacer.stl"/>
      </geometry>
      <material name="pink">
        <color rgba="0.8 0.0 0.4 1"/>
      </material>
    </visual>
    <collision>
      <origin rpy="0 0 0" xyz="0 0 0"/>
      <geometry>
        <cylinder length="0.0806" radius="0.012"/>
      </geometry>
    </collision>
    <inertial>
      <mass value="0.060"/>
      <origin xyz="0 0 0"/>
      <inertia ixx="0.000206991" ixy="0.0" ixz="0.0" iyy="0.000206991" iyz="0.0" izz="0.000001080"/>
    </inertial>
  </link>
  <gazebo reference="standoff_81mm_12_link">
    <material>Gazebo/Black</material>
    <selfCollide>true</selfCollide>
    <gravity>true</gravity>
  </gazebo>
  <joint name="standoff_81mm_13_joint" type="fixed">
    <origin rpy="0 0 0" xyz="-0.104 -0.098 0.3962"/>
    <parent link="base_link"/>
    <child link="standoff_81mm_13_link"/>
  </joint>
  <link name="standoff_81mm_13_link">
    <visual>
      <origin rpy="0 0 0" xyz=" 0 0 0"/>
      <geometry>
        <mesh filename="package://turtlebot2i_description/meshes/stacks/interbotix/81mm_Spacer.stl"/>
      </geometry>
      <material name="pink">
        <color rgba="0.8 0.0 0.4 1"/>
      </material>
    </visual>
    <collision>
      <origin rpy="0 0 0" xyz="0 0 0"/>
      <geometry>
        <cylinder length="0.0806" radius="0.012"/>
      </geometry>
    </collision>
    <inertial>
      <mass value="0.060"/>
      <origin xyz="0 0 0"/>
      <inertia ixx="0.000206991" ixy="0.0" ixz="0.0" iyy="0.000206991" iyz="0.0" izz="0.000001080"/>
    </inertial>
  </link>
  <gazebo reference="standoff_81mm_13_link">
    <material>Gazebo/Black</material>
    <selfCollide>true</selfCollide>
    <gravity>true</gravity>
  </gazebo>
  <joint name="plate_top_joint" type="fixed">
    <origin rpy="0 0 0" xyz="0.0 0.0 0.4388"/>
    <parent link="base_link"/>
    <child link="plate_top_link"/>
  </joint>
  <link name="plate_top_link">
    <visual>
      <origin rpy="0 0 0" xyz="0 0 0"/>
      <geometry>
        <mesh filename="package://turtlebot2i_description/meshes/stacks/interbotix/TurtleBot2i_TopPlate.stl"/>
      </geometry>
      <material name="near_black">
        <color rgba="0.125 0.125 0.125 1"/>
      </material>
    </visual>
    <collision>
      <origin rpy="0 0 0" xyz="0 0 0"/>
      <geometry>
        <mesh filename="package://turtlebot2i_description/meshes/stacks/interbotix/TurtleBot2i_TopPlate.stl"/>
      </geometry>
    </collision>
    <inertial>
      <mass value="0.377"/>
      <origin xyz="0 0 0"/>
      <inertia ixx="0.003328" ixy="0.0" ixz="0.0" iyy="0.003328" iyz="0.0" izz="0.006656"/>
    </inertial>
  </link>
  <gazebo reference="plate_top_link">
    <material>Gazebo/Black</material>
    <selfCollide>true</selfCollide>
    <gravity>true</gravity>
  </gazebo>
  <joint name="standoff_251mm_0_joint" type="fixed">
    <origin rpy="0 0 0" xyz="0.069 0.13 0.311"/>
    <parent link="base_link"/>
    <child link="standoff_251mm_0_link"/>
  </joint>
  <link name="standoff_251mm_0_link">
    <visual>
      <origin rpy="0 0 0" xyz=" 0 0 0"/>
      <geometry>
        <mesh filename="package://turtlebot2i_description/meshes/stacks/interbotix/251mm_Spacer.stl"/>
      </geometry>
      <material name="pink">
        <color rgba="0.8 0.0 0.4 1"/>
      </material>
    </visual>
    <collision>
      <origin rpy="0 0 0" xyz="0 0 0"/>
      <geometry>
        <cylinder length="0.251" radius="0.012"/>
      </geometry>
    </collision>
    <inertial>
      <mass value="0.031"/>
      <origin xyz="0 0 0"/>
      <inertia ixx="0.000206991" ixy="0.0" ixz="0.0" iyy="0.000206991" iyz="0.0" izz="0.000001080"/>
    </inertial>
  </link>
  <gazebo reference="standoff_251mm_0_link">
    <material>Gazebo/Black</material>
    <selfCollide>true</selfCollide>
    <gravity>true</gravity>
  </gazebo>
  <joint name="standoff_251mm_1_joint" type="fixed">
    <origin rpy="0 0 0" xyz="0.069 -0.13 0.311"/>
    <parent link="base_link"/>
    <child link="standoff_251mm_1_link"/>
  </joint>
  <link name="standoff_251mm_1_link">
    <visual>
      <origin rpy="0 0 0" xyz=" 0 0 0"/>
      <geometry>
        <mesh filename="package://turtlebot2i_description/meshes/stacks/interbotix/251mm_Spacer.stl"/>
      </geometry>
      <material name="pink">
        <color rgba="0.8 0.0 0.4 1"/>
      </material>
    </visual>
    <collision>
      <origin rpy="0 0 0" xyz="0 0 0"/>
      <geometry>
        <cylinder length="0.251" radius="0.012"/>
      </geometry>
    </collision>
    <inertial>
      <mass value="0.031"/>
      <origin xyz="0 0 0"/>
      <inertia ixx="0.000206991" ixy="0.0" ixz="0.0" iyy="0.000206991" iyz="0.0" izz="0.000001080"/>
    </inertial>
  </link>
  <gazebo reference="standoff_251mm_1_link">
    <material>Gazebo/Black</material>
    <selfCollide>true</selfCollide>
    <gravity>true</gravity>
  </gazebo>
  <joint name="camera_rgb_joint" type="fixed">
    <origin rpy="0 0 0" xyz="-0.05 0.0 0.3051"/>
    <parent link="base_link"/>
    <child link="camera_rgb_frame"/>
  </joint>
  <link name="camera_rgb_frame"/>
  <joint name="camera_rgb_optical_joint" type="fixed">
    <origin rpy="-1.570795 0 -1.570795" xyz="0 0.012 0"/>
    <parent link="camera_rgb_frame"/>
    <child link="camera_rgb_optical_frame"/>
  </joint>
  <link name="camera_rgb_optical_frame"/>
  <joint name="camera_joint" type="fixed">
    <origin rpy="0 0 0" xyz="0 0 0"/>
    <parent link="camera_rgb_frame"/>
    <child link="camera_link"/>
  </joint>
  <link name="camera_link">
    <visual>
      <origin rpy="0 0 0" xyz="0 0 0"/>
      <geometry>
        <mesh filename="package://turtlebot2i_description/meshes/sensors/astra_new.stl"/>
      </geometry>
      <material name="black">
        <color rgba="0.1 0.1 0.1 1"/>
      </material>
    </visual>
    <collision>
      <origin rpy="0 0 0" xyz="-0.017 0.0 0.0"/>
      <geometry>
        <box size="0.0440 0.1650 0.0300"/>
      </geometry>
    </collision>
    <inertial>
      <mass value="0.3"/>
      <origin xyz="0 0 0"/>
      <inertia ixx="0.003881243" ixy="0.0" ixz="0.0" iyy="0.000498940" iyz="0.0" izz="0.003879257"/>
    </inertial>
  </link>
  <gazebo reference="camera_link">
    <material>Gazebo/Blue</material>
    <selfCollide>true</selfCollide>
    <gravity>true</gravity>
  </gazebo>
  <joint name="camera_depth_joint" type="fixed">
    <origin rpy="0 0 0" xyz="0 0.038 0"/>
    <parent link="camera_rgb_frame"/>
    <child link="camera_depth_frame"/>
  </joint>
  <link name="camera_depth_frame"/>
  <joint name="camera_depth_optical_joint" type="fixed">
    <origin rpy="-1.570795 0 -1.570795" xyz="0 0 0"/>
    <parent link="camera_depth_frame"/>
    <child link="camera_depth_optical_frame"/>
  </joint>
  <link name="camera_depth_optical_frame"/>
  <gazebo reference="camera_link">
    <sensor name="camera" type="depth">
      <always_on>true</always_on>
      <update_rate>20.0</update_rate>
      <camera>
        <horizontal_fov>1.04719666667</horizontal_fov>
        <image>
          <format>B8G8R8</format>
          <width>640</width>
          <height>480</height>
        </image>
        <clip>
          <near>0.05</near>
          <far>8.0</far>
        </clip>
      </camera>
      <plugin filename="libgazebo_ros_openni_kinect.so" name="kinect_camera_controller">
        <cameraName>camera</cameraName>
        <alwaysOn>true</alwaysOn>
        <updateRate>10</updateRate>
        <imageTopicName>rgb/image_raw</imageTopicName>
        <depthImageTopicName>depth/image_raw</depthImageTopicName>
        <pointCloudTopicName>depth/points</pointCloudTopicName>
        <cameraInfoTopicName>rgb/camera_info</cameraInfoTopicName>
        <depthImageCameraInfoTopicName>depth/camera_info</depthImageCameraInfoTopicName>
        <frameName>camera_depth_optical_frame</frameName>
        <baseline>0.1</baseline>
        <distortion_k1>0.0</distortion_k1>
        <distortion_k2>0.0</distortion_k2>
        <distortion_k3>0.0</distortion_k3>
        <distortion_t1>0.0</distortion_t1>
        <distortion_t2>0.0</distortion_t2>
        <pointCloudCutoff>0.4</pointCloudCutoff>
      </plugin>
    </sensor>
  </gazebo>
  <!--
    ==  Intel SR300 body joints & links ==
    -->
  <!-- camera_sr300 body -->
  <joint name="camera_sr300_joint" type="fixed">
    <origin rpy="0 1.16 0" xyz="0.142 0.0 0.428"/>
    <parent link="base_link"/>
    <child link="camera_sr300"/>
  </joint>
  <link name="camera_sr300">
    <visual>
      <origin rpy="0 0 0" xyz="0 0 0"/>
      <geometry>
        <mesh filename="package://turtlebot2i_description/meshes/sensors/sr300.stl"/>
      </geometry>
      <material name="black">
        <color rgba="0.1 0.1 0.1 1"/>
      </material>
    </visual>
    <collision>
      <origin rpy="0 0 0" xyz="0.0 0.0 0.0"/>
      <geometry>
        <mesh filename="package://turtlebot2i_description/meshes/sensors/sr300.stl" scale="2.0 2.0 2.0"/>
      </geometry>
    </collision>
    <!-- This inertial field needs doesn't contain reliable data!! -->
    <inertial>
      <mass value="0.15"/>
      <origin xyz="0 0 0"/>
      <inertia ixx="0.003881243" ixy="0.0" ixz="0.0" iyy="0.000498940" iyz="0.0" izz="0.003879257"/>
    </inertial>
  </link>
  <gazebo reference="camera_sr300">
    <material>Gazebo/Blue</material>
    <selfCollide>true</selfCollide>
    <gravity>true</gravity>
  </gazebo>
  <!--
    ==  RGB joints & links ==
    -->
  <joint name="camera_sr300_rgb_joint" type="fixed">
    <origin rpy="0 0 0" xyz="0.012 0.003 0.0"/>
    <parent link="camera_sr300"/>
    <child link="camera_sr300_rgb_frame"/>
  </joint>
  <link name="camera_sr300_rgb_frame"/>
  <joint name="camera_sr300_rgb_optical_joint" type="fixed">
    <origin rpy="-1.570795 0 -1.570795" xyz="0 0 0"/>
    <parent link="camera_sr300_rgb_frame"/>
    <child link="camera_sr300_rgb_optical_frame"/>
  </joint>
  <link name="camera_sr300_rgb_optical_frame"/>
  <!--
    ==  Depth joints & links ==
    -->
  <joint name="camera_sr300_depth_joint" type="fixed">
    <origin rpy="0 0 0" xyz="0 -0.024 0"/>
    <parent link="camera_sr300_rgb_frame"/>
    <child link="camera_sr300_depth_frame"/>
  </joint>
  <link name="camera_sr300_depth_frame"/>
  <joint name="camera_sr300_depth_optical_joint" type="fixed">
    <origin rpy="-1.570795 0 -1.570795" xyz="0 0 0"/>
    <parent link="camera_sr300_depth_frame"/>
    <child link="camera_sr300_depth_optical_frame"/>
  </joint>
  <link name="camera_sr300_depth_optical_frame"/>
  <!-- Simulation sensor -->
  <gazebo reference="camera_sr300">
    <sensor name="camera_sr300" type="depth">
      <always_on>true</always_on>
      <update_rate>20.0</update_rate>
      <camera>
        <horizontal_fov>1.04719666667</horizontal_fov>
        <image>
          <format>B8G8R8</format>
          <width>640</width>
          <height>480</height>
        </image>
        <clip>
          <near>0.05</near>
          <far>8.0</far>
        </clip>
      </camera>
      <plugin filename="libgazebo_ros_openni_kinect.so" name="kinect_camera_controller">
        <cameraName>camera_sr300</cameraName>
        <alwaysOn>true</alwaysOn>
        <updateRate>10</updateRate>
        <imageTopicName>rgb/image_raw</imageTopicName>
        <depthImageTopicName>depth/image_raw</depthImageTopicName>
        <pointCloudTopicName>depth/points</pointCloudTopicName>
        <cameraInfoTopicName>rgb/camera_info</cameraInfoTopicName>
        <depthImageCameraInfoTopicName>depth/camera_info</depthImageCameraInfoTopicName>
        <frameName>camera_sr300_depth_optical_frame</frameName>
        <baseline>0.1</baseline>
        <distortion_k1>0.0</distortion_k1>
        <distortion_k2>0.0</distortion_k2>
        <distortion_k3>0.0</distortion_k3>
        <distortion_t1>0.0</distortion_t1>
        <distortion_t2>0.0</distortion_t2>
        <pointCloudCutoff>0.2</pointCloudCutoff>
      </plugin>
    </sensor>
  </gazebo>
  <joint name="arm_base_joint" type="fixed">
    <origin xyz="0.145 0.0 0.112"/>
    <parent link="base_link"/>
    <child link="arm_base_link"/>
  </joint>
  <link name="arm_base_link">
    <!-- TODO: This inertial field needs doesn't contain reliable data!! -->
    <inertial>
      <mass value="0.055"/>
      <origin xyz="0 0 0"/>
      <inertia ixx="0.000017012" ixy="0.0" ixz="0.0" iyy="0.000013258" iyz="0.0" izz="0.000009483"/>
    </inertial>
    <visual>
      <origin rpy="0 0 0" xyz="0 0 0"/>
      <geometry>
        <mesh filename="package://phantomx_pincher_arm_description/meshes/PincherBase.stl" scale="1.0 1.0 1.0"/>
      </geometry>
      <material name="Black"/>
    </visual>
    <collision>
      <origin rpy="0 0 0" xyz="0 0 0"/>
      <geometry>
        <mesh filename="package://phantomx_pincher_arm_description/meshes/PincherBase.stl" scale="1.0 1.0 1.0"/>
      </geometry>
    </collision>
  </link>
  <gazebo reference="arm_base_link">
    <material>Gazebo/Black</material>
    <gravity>true</gravity>
  </gazebo>
  <joint name="arm_shoulder_pan_joint" type="revolute">
    <origin rpy="0 0 0" xyz="0 0 0.020"/>
    <axis xyz="0 0 1"/>
    <limit effort="6" lower="-1.74" upper="1.74" velocity="1.571"/>
    <dynamics friction="0.13"/>
    <parent link="arm_base_link"/>
    <child link="arm_shoulder_pan_link"/>
  </joint>
  <link name="arm_shoulder_pan_link">
    <!-- TODO: This inertial field needs doesn't contain reliable data!! -->
    <inertial>
      <mass value="0.008"/>
      <origin xyz="0 0 0"/>
      <inertia ixx="0.000001" ixy="0.0" ixz="0.0" iyy="0.000001" iyz="0.0" izz="0.000001"/>
    </inertial>
    <visual>
      <origin rpy="0 0 0" xyz="0 0 0"/>
      <geometry>
        <mesh filename="package://phantomx_pincher_arm_description/meshes/F2Bracket.stl" scale="1.0 1.0 1.0"/>
      </geometry>
      <material name="Red"/>
    </visual>
    <collision>
      <origin rpy="0 0 0" xyz="0 0 0"/>
      <geometry>
        <mesh filename="package://phantomx_pincher_arm_description/meshes/F2Bracket.stl" scale="1.0 1.0 1.0"/>
      </geometry>
    </collision>
  </link>
  <gazebo reference="arm_shoulder_pan_link">
    <material>Gazebo/Red</material>
    <gravity>true</gravity>
  </gazebo>
  <transmission name="arm_shoulder_pan_transmission">
    <type>transmission_interface/SimpleTransmission</type>
    <joint name="arm_shoulder_pan_joint">
      <hardwareInterface>EffortJointInterface</hardwareInterface>
    </joint>
    <actuator name="arm_shoulder_pan_actuator">
      <hardwareInterface>EffortJointInterface</hardwareInterface>
      <mechanicalReduction>1</mechanicalReduction>
    </actuator>
  </transmission>
  <joint name="arm_bicep_joint" type="revolute">
    <origin rpy="0 0 0" xyz="0 0 0.027"/>
    <axis xyz="0 1 0"/>
    <limit effort="6" lower="-1.98" upper="1.88" velocity="1.571"/>
    <dynamics friction="0.13"/>
    <parent link="arm_shoulder_pan_link"/>
    <child link="arm_bicep_link"/>
  </joint>
  <link name="arm_bicep_link">
    <!-- TODO: This inertial field needs doesn't contain reliable data!! -->
    <inertial>
      <mass value="0.016"/>
      <origin xyz="0 0 0"/>
      <inertia ixx="0.000001" ixy="0.0" ixz="0.0" iyy="0.000001" iyz="0.0" izz="0.000001"/>
    </inertial>
    <visual>
      <origin rpy="0 0 0" xyz=" 0 0 0 "/>
      <geometry>
        <mesh filename="package://phantomx_pincher_arm_description/meshes/PincherBicep.stl" scale="1.0 1.0 1.0"/>
      </geometry>
      <material name="Red"/>
    </visual>
    <collision>
      <origin rpy="0 0 0" xyz="0.0 0.0 0.0"/>
      <geometry>
        <mesh filename="package://phantomx_pincher_arm_description/meshes/PincherBicep.stl" scale="1.0 1.0 1.0"/>
      </geometry>
    </collision>
  </link>
  <gazebo reference="arm_bicep_link">
    <material>Gazebo/Red</material>
    <gravity>true</gravity>
  </gazebo>
  <transmission name="arm_bicep_transmission">
    <type>transmission_interface/SimpleTransmission</type>
    <joint name="arm_bicep_joint">
      <hardwareInterface>EffortJointInterface</hardwareInterface>
    </joint>
    <actuator name="arm_bicep_actuator">
      <hardwareInterface>EffortJointInterface</hardwareInterface>
      <mechanicalReduction>1</mechanicalReduction>
    </actuator>
  </transmission>
  <joint name="arm_forearm_joint" type="revolute">
    <origin rpy="0 0 0" xyz="0.0325 0 0.104"/>
    <axis xyz="0 -1 0"/>
    <limit effort="6" lower="-1.58" upper="0.59" velocity="1.571"/>
    <dynamics friction="0.13"/>
    <parent link="arm_bicep_link"/>
    <child link="arm_forearm_link"/>
  </joint>
  <link name="arm_forearm_link">
    <!-- TODO: This inertial field needs doesn't contain reliable data!! -->
    <inertial>
      <mass value="0.016"/>
      <origin xyz="0 0 0"/>
      <inertia ixx="0.000001" ixy="0.0" ixz="0.0" iyy="0.000001" iyz="0.0" izz="0.000001"/>
    </inertial>
    <visual>
      <origin rpy="0 0 0" xyz=" 0 0 0 "/>
      <geometry>
        <mesh filename="package://phantomx_pincher_arm_description/meshes/PincherForeArm.stl" scale="1.0 1.0 1.0"/>
      </geometry>
      <material name="Red"/>
    </visual>
    <collision>
      <origin rpy="0 0 0" xyz="0.0 0.0 0.0"/>
      <geometry>
        <mesh filename="package://phantomx_pincher_arm_description/meshes/PincherForeArm.stl" scale="1.0 1.0 1.0"/>
      </geometry>
    </collision>
  </link>
  <gazebo reference="arm_forearm_link">
    <material>Gazebo/Red</material>
    <gravity>true</gravity>
  </gazebo>
  <transmission name="arm_forearm_transmission">
    <type>transmission_interface/SimpleTransmission</type>
    <joint name="arm_forearm_joint">
      <hardwareInterface>EffortJointInterface</hardwareInterface>
    </joint>
    <actuator name="arm_forearm_actuator">
      <hardwareInterface>EffortJointInterface</hardwareInterface>
      <mechanicalReduction>1</mechanicalReduction>
    </actuator>
  </transmission>
  <joint name="arm_wrist_flex_joint" type="revolute">
    <origin rpy="0 0 0" xyz="0.104 0 0"/>
    <axis xyz="0 -1 0"/>
    <limit effort="6" lower="-1.79" upper="1.67" velocity="1.571"/>
    <dynamics friction="0.13"/>
    <parent link="arm_forearm_link"/>
    <child link="arm_wrist_flex_link"/>
  </joint>
  <link name="arm_wrist_flex_link">
    <!-- TODO: This inertial field needs doesn't contain reliable data!! -->
    <inertial>
      <mass value="0.01"/>
      <origin xyz="0 0 0"/>
      <inertia ixx="0.000001" ixy="0.0" ixz="0.0" iyy="0.000001" iyz="0.0" izz="0.000001"/>
    </inertial>
    <visual>
      <origin rpy="0 0 0" xyz=" 0 0 0 "/>
      <geometry>
        <mesh filename="package://phantomx_pincher_arm_description/meshes/PincherWristGripper.stl" scale="1.0 1.0 1.0"/>
      </geometry>
      <material name="Red"/>
    </visual>
    <collision>
      <origin rpy="0 0 0" xyz="0.0 0.0 0.0"/>
      <geometry>
        <mesh filename="package://phantomx_pincher_arm_description/meshes/PincherWristGripper.stl" scale="1.0 1.0 1.0"/>
      </geometry>
    </collision>
  </link>
  <gazebo reference="arm_wrist_flex_link">
    <material>Gazebo/Red</material>
    <gravity>true</gravity>
  </gazebo>
  <transmission name="arm_wrist_flex_transmission">
    <type>transmission_interface/SimpleTransmission</type>
    <joint name="arm_wrist_flex_joint">
      <hardwareInterface>EffortJointInterface</hardwareInterface>
    </joint>
    <actuator name="arm_wrist_flex_actuator">
      <hardwareInterface>EffortJointInterface</hardwareInterface>
      <mechanicalReduction>1</mechanicalReduction>
    </actuator>
  </transmission>
  <!-- gripper joint -->
  <!-- Finger 1 -->
  <joint name="gripper_joint" type="prismatic">
    <origin rpy="0 0 0" xyz="0.070 0 0"/>
    <axis xyz="0 1 0"/>
    <limit effort="30" lower="0.002" upper="0.032" velocity="0.5"/>
    <parent link="arm_wrist_flex_link"/>
    <child link="gripper_active_link"/>
  </joint>
  <link name="gripper_active_link">
    <inertial>
      <!-- TODO: This inertial field needs doesn't contain reliable data!! -->
      <mass value="0.01"/>
      <origin xyz="0 0 0"/>
      <inertia ixx="0.000001" ixy="0.0" ixz="0.0" iyy="0.000001" iyz="0.0" izz="0.000001"/>
    </inertial>
    <visual>
      <origin rpy="0 0 0" xyz="0 0 0"/>
      <geometry>
        <mesh filename="package://phantomx_pincher_arm_description/meshes/PincherFinger.stl" scale="1.0 1.0 1.0"/>
      </geometry>
      <material name="Red"/>
    </visual>
    <collision>
      <origin rpy="0 0 0" xyz="0 0 0"/>
      <geometry>
        <mesh filename="package://phantomx_pincher_arm_description/meshes/PincherFinger.stl" scale="1.0 1.0 1.0"/>
      </geometry>
    </collision>
  </link>
  <gazebo reference="gripper_active_link">
    <material>Gazebo/Red</material>
    <!--selfCollide>true</selfCollide-->
    <gravity>true</gravity>
  </gazebo>
  <!-- Finger 2 -->
  <!-- Note: currently static but should be a Mimic of Finger 1 -->
  <joint name="gripper2_joint" type="fixed">
    <origin rpy="0 0 0" xyz="0.070 -0.016 0"/>
    <parent link="arm_wrist_flex_link"/>
    <child link="gripper_active2_link"/>
  </joint>
  <link name="gripper_active2_link">
    <inertial>
      <!-- TODO: This inertial field needs doesn't contain reliable data!! -->
      <mass value="0.01"/>
      <origin xyz="0 0 0"/>
      <inertia ixx="0.000001" ixy="0.0" ixz="0.0" iyy="0.000001" iyz="0.0" izz="0.000001"/>
    </inertial>
    <visual>
      <origin rpy="3.14159 0 0" xyz="0 0 0"/>
      <geometry>
        <mesh filename="package://phantomx_pincher_arm_description/meshes/PincherFinger.stl" scale="1.0 1.0 1.0"/>
      </geometry>
      <material name="Red"/>
    </visual>
    <collision>
      <origin rpy="3.14159 0 0" xyz="0 0 0"/>
      <geometry>
        <mesh filename="package://phantomx_pincher_arm_description/meshes/PincherFinger.stl" scale="1.0 1.0 1.0"/>
      </geometry>
    </collision>
  </link>
  <gazebo reference="gripper_active2_link">
    <material>Gazebo/Red</material>
    <!--selfCollide>true</selfCollide-->
    <gravity>true</gravity>
  </gazebo>
  <!-- Using Mimic -->
  <!-- gripper 2 joint -->
  <!--  TODO: Test Mimic ->
    <joint name="gripper2_joint" type="prismatic">
      <origin xyz="0.070 0 0" rpy="0 0 0"/>
      <axis xyz="0 1 0"/>
      <limit effort="30" velocity="0.5" lower="-0.016" upper="-0.002"/>
      <parent link="arm_wrist_flex_link"/>
      <child link="gripper_active2_link"/>
      <mimic joint="gripper_joint" multiplier="-1"  offset = "0"/>
    </joint-->
  <!-- gripper_link -->
  <link name="gripper_link"/>
  <joint name="gripper_link_joint" type="revolute">
    <origin rpy="0 0 0" xyz="0.110 0 0"/>
    <parent link="arm_wrist_flex_link"/>
    <child link="gripper_link"/>
    <limit effort="6" lower="-3.14" upper="3.14" velocity="1"/>
    <axis xyz="1 0 0"/>
  </joint>
  <!--gazebo>
      <gripper name="gripper">
        <grasp_check>
          <attach_steps>5</attach_steps>
          <detach_steps>10</detach_steps>
          <min_contact_count>2</min_contact_count>
        </grasp_check>
      </gripper>
      <gripper_link>gripper_active_link</gripper_link>
      <palm_link>gripper_servo_link</palm_link>
  </gazebo-->
</robot>
