<?xml version="1.0" ?>
<!-- =================================================================================== -->
<!-- |    This document was autogenerated by xacro from phantomx_pincher_arm.urdf.xacro | -->
<!-- |    EDITING THIS FILE BY HAND IS NOT RECOMMENDED                                 | -->
<!-- =================================================================================== -->
<!-- Describe URDF for PhantomX Pincher Arm -->
<robot name="phantomx_pincher_arm" xmlns:xacro="http://ros.org/wiki/xacro">
  <!-- As we don't have a base here, add a base_link link as location reference -->
  <link name="base_link"/>
  <joint name="arm_base_joint" type="fixed">
    <origin xyz="0.0 0.00 0.077"/>
    <parent link="base_link"/>
    <child link="arm_base_link"/>
  </joint>
  <link name="arm_base_link">
    <!-- TODO: This inertial field needs doesn't contain reliable data!! -->
    <inertial>
      <mass value="0.055"/>
      <origin xyz="0 0 0"/>
      <inertia ixx="0.000017012" ixy="0.0" ixz="0.0" iyy="0.000013258" iyz="0.0" izz="0.000009483"/>
    </inertial>
    <visual>
      <origin rpy="0 0 0" xyz="0 0 0"/>
      <geometry>
        <mesh filename="package://phantomx_pincher_arm_description/meshes/PincherBase.stl" scale="1.0 1.0 1.0"/>
      </geometry>
      <material name="Black"/>
    </visual>
    <collision>
      <origin rpy="0 0 0" xyz="0 0 0"/>
      <geometry>
        <mesh filename="package://phantomx_pincher_arm_description/meshes/PincherBase.stl" scale="1.0 1.0 1.0"/>
      </geometry>
    </collision>
  </link>
  <gazebo reference="arm_base_link">
    <material>Gazebo/Black</material>
    <gravity>true</gravity>
  </gazebo>
  <joint name="PhantomXPincher_joint1" type="revolute">
    <origin rpy="0 0 0" xyz="0 0 0.020"/>
    <axis xyz="0 0 1"/>
    <limit effort="6" lower="-1.74" upper="1.74" velocity="1.571"/>
    <dynamics friction="0.13"/>
    <parent link="arm_base_link"/>
    <child link="arm_shoulder_pan_link"/>
  </joint>
  <link name="arm_shoulder_pan_link">
    <!-- TODO: This inertial field needs doesn't contain reliable data!! -->
    <inertial>
      <mass value="0.008"/>
      <origin xyz="0 0 0"/>
      <inertia ixx="0.000001" ixy="0.0" ixz="0.0" iyy="0.000001" iyz="0.0" izz="0.000001"/>
    </inertial>
    <visual>
      <origin rpy="0 0 0" xyz="0 0 0"/>
      <geometry>
        <mesh filename="package://phantomx_pincher_arm_description/meshes/F2Bracket.stl" scale="1.0 1.0 1.0"/>
      </geometry>
      <material name="White"/>
    </visual>
    <collision>
      <origin rpy="0 0 0" xyz="0 0 0"/>
      <geometry>
        <mesh filename="package://phantomx_pincher_arm_description/meshes/F2Bracket.stl" scale="1.0 1.0 1.0"/>
      </geometry>
    </collision>
  </link>
  <gazebo reference="arm_shoulder_pan_link">
    <material>Gazebo/White</material>
    <gravity>true</gravity>
  </gazebo>
  <transmission name="arm_shoulder_pan_transmission">
    <type>transmission_interface/SimpleTransmission</type>
    <joint name="PhantomXPincher_joint1">
      <hardwareInterface>EffortJointInterface</hardwareInterface>
    </joint>
    <actuator name="arm_shoulder_pan_actuator">
      <hardwareInterface>EffortJointInterface</hardwareInterface>
      <mechanicalReduction>1</mechanicalReduction>
    </actuator>
  </transmission>
  <joint name="PhantomXPincher_joint2" type="revolute">
    <origin rpy="0 0 0" xyz="0 0 0.027"/>
    <axis xyz="0 1 0"/>
    <limit effort="6" lower="-1.98" upper="1.88" velocity="1.571"/>
    <dynamics friction="0.13"/>
    <parent link="arm_shoulder_pan_link"/>
    <child link="arm_bicep_link"/>
  </joint>
  <link name="arm_bicep_link">
    <!-- TODO: This inertial field needs doesn't contain reliable data!! -->
    <inertial>
      <mass value="0.016"/>
      <origin xyz="0 0 0"/>
      <inertia ixx="0.000001" ixy="0.0" ixz="0.0" iyy="0.000001" iyz="0.0" izz="0.000001"/>
    </inertial>
    <visual>
      <origin rpy="0 0 0" xyz=" 0 0 0 "/>
      <geometry>
        <mesh filename="package://phantomx_pincher_arm_description/meshes/PincherBicep.stl" scale="1.0 1.0 1.0"/>
      </geometry>
      <material name="White"/>
    </visual>
    <collision>
      <origin rpy="0 0 0" xyz="0.0 0.0 0.0"/>
      <geometry>
        <mesh filename="package://phantomx_pincher_arm_description/meshes/PincherBicep.stl" scale="1.0 1.0 1.0"/>
      </geometry>
    </collision>
  </link>
  <gazebo reference="arm_bicep_link">
    <material>Gazebo/White</material>
    <gravity>true</gravity>
  </gazebo>
  <transmission name="arm_bicep_transmission">
    <type>transmission_interface/SimpleTransmission</type>
    <joint name="PhantomXPincher_joint2">
      <hardwareInterface>EffortJointInterface</hardwareInterface>
    </joint>
    <actuator name="arm_bicep_actuator">
      <hardwareInterface>EffortJointInterface</hardwareInterface>
      <mechanicalReduction>1</mechanicalReduction>
    </actuator>
  </transmission>
  <joint name="PhantomXPincher_joint3" type="revolute">
    <origin rpy="0 0 0" xyz="0.0325 0 0.104"/>
    <axis xyz="0 -1 0"/>
    <limit effort="6" lower="-1.58" upper="0.59" velocity="1.571"/>
    <dynamics friction="0.13"/>
    <parent link="arm_bicep_link"/>
    <child link="arm_forearm_link"/>
  </joint>
  <link name="arm_forearm_link">
    <!-- TODO: This inertial field needs doesn't contain reliable data!! -->
    <inertial>
      <mass value="0.016"/>
      <origin xyz="0 0 0"/>
      <inertia ixx="0.000001" ixy="0.0" ixz="0.0" iyy="0.000001" iyz="0.0" izz="0.000001"/>
    </inertial>
    <visual>
      <origin rpy="0 0 0" xyz=" 0 0 0 "/>
      <geometry>
        <mesh filename="package://phantomx_pincher_arm_description/meshes/PincherForeArm.stl" scale="1.0 1.0 1.0"/>
      </geometry>
      <material name="White"/>
    </visual>
    <collision>
      <origin rpy="0 0 0" xyz="0.0 0.0 0.0"/>
      <geometry>
        <mesh filename="package://phantomx_pincher_arm_description/meshes/PincherForeArm.stl" scale="1.0 1.0 1.0"/>
      </geometry>
    </collision>
  </link>
  <gazebo reference="arm_forearm_link">
    <material>Gazebo/White</material>
    <gravity>true</gravity>
  </gazebo>
  <transmission name="arm_forearm_transmission">
    <type>transmission_interface/SimpleTransmission</type>
    <joint name="PhantomXPincher_joint3">
      <hardwareInterface>EffortJointInterface</hardwareInterface>
    </joint>
    <actuator name="arm_forearm_actuator">
      <hardwareInterface>EffortJointInterface</hardwareInterface>
      <mechanicalReduction>1</mechanicalReduction>
    </actuator>
  </transmission>
  <joint name="PhantomXPincher_joint4" type="revolute">
    <origin rpy="0 0 0" xyz="0.104 0 0"/>
    <axis xyz="0 -1 0"/>
    <limit effort="6" lower="-1.79" upper="1.67" velocity="1.571"/>
    <dynamics friction="0.13"/>
    <parent link="arm_forearm_link"/>
    <child link="arm_wrist_flex_link"/>
  </joint>
  <link name="arm_wrist_flex_link">
    <!-- TODO: This inertial field needs doesn't contain reliable data!! -->
    <inertial>
      <mass value="0.01"/>
      <origin xyz="0 0 0"/>
      <inertia ixx="0.000001" ixy="0.0" ixz="0.0" iyy="0.000001" iyz="0.0" izz="0.000001"/>
    </inertial>
    <visual>
      <origin rpy="0 0 0" xyz=" 0 0 0 "/>
      <geometry>
        <mesh filename="package://phantomx_pincher_arm_description/meshes/PincherWristGripper.stl" scale="1.0 1.0 1.0"/>
      </geometry>
      <material name="White"/>
    </visual>
    <collision>
      <origin rpy="0 0 0" xyz="0.0 0.0 0.0"/>
      <geometry>
        <mesh filename="package://phantomx_pincher_arm_description/meshes/PincherWristGripper.stl" scale="1.0 1.0 1.0"/>
      </geometry>
    </collision>
  </link>
  <gazebo reference="arm_wrist_flex_link">
    <material>Gazebo/White</material>
    <gravity>true</gravity>
  </gazebo>
  <transmission name="arm_wrist_flex_transmission">
    <type>transmission_interface/SimpleTransmission</type>
    <joint name="PhantomXPincher_joint4">
      <hardwareInterface>EffortJointInterface</hardwareInterface>
    </joint>
    <actuator name="arm_wrist_flex_actuator">
      <hardwareInterface>EffortJointInterface</hardwareInterface>
      <mechanicalReduction>1</mechanicalReduction>
    </actuator>
  </transmission>
  <!-- gripper joint -->
  <!-- Finger 1 -->
  <joint name="PhantomXPincher_gripperClose_joint" type="prismatic">
    <origin rpy="0 0 0" xyz="0.070 0 0"/>
    <axis xyz="0 1 0"/>
    <limit effort="30" lower="0.002" upper="0.032" velocity="0.5"/>
    <parent link="arm_wrist_flex_link"/>
    <child link="gripper_active_link"/>
  </joint>
  <link name="gripper_active_link">
    <inertial>
      <!-- TODO: This inertial field needs doesn't contain reliable data!! -->
      <mass value="0.01"/>
      <origin xyz="0 0 0"/>
      <inertia ixx="0.000001" ixy="0.0" ixz="0.0" iyy="0.000001" iyz="0.0" izz="0.000001"/>
    </inertial>
    <visual>
      <origin rpy="0 0 0" xyz="0 0 0"/>
      <geometry>
        <mesh filename="package://phantomx_pincher_arm_description/meshes/PincherFinger.stl" scale="1.0 1.0 1.0"/>
      </geometry>
      <material name="White"/>
    </visual>
    <collision>
      <origin rpy="0 0 0" xyz="0 0 0"/>
      <geometry>
        <mesh filename="package://phantomx_pincher_arm_description/meshes/PincherFinger.stl" scale="1.0 1.0 1.0"/>
      </geometry>
    </collision>
  </link>
  <gazebo reference="gripper_active_link">
    <material>Gazebo/White</material>
    <!--selfCollide>true</selfCollide-->
    <gravity>true</gravity>
  </gazebo>
  <!-- Finger 2 -->
  <!-- Note: currently static but should be a Mimic of Finger 1 -->
  <joint name="gripper2_joint" type="fixed">
    <origin rpy="0 0 0" xyz="0.070 -0.016 0"/>
    <parent link="arm_wrist_flex_link"/>
    <child link="gripper_active2_link"/>
  </joint>
  <link name="gripper_active2_link">
    <inertial>
      <!-- TODO: This inertial field needs doesn't contain reliable data!! -->
      <mass value="0.01"/>
      <origin xyz="0 0 0"/>
      <inertia ixx="0.000001" ixy="0.0" ixz="0.0" iyy="0.000001" iyz="0.0" izz="0.000001"/>
    </inertial>
    <visual>
      <origin rpy="3.14159 0 0" xyz="0 0 0"/>
      <geometry>
        <mesh filename="package://phantomx_pincher_arm_description/meshes/PincherFinger.stl" scale="1.0 1.0 1.0"/>
      </geometry>
      <material name="White"/>
    </visual>
    <collision>
      <origin rpy="3.14159 0 0" xyz="0 0 0"/>
      <geometry>
        <mesh filename="package://phantomx_pincher_arm_description/meshes/PincherFinger.stl" scale="1.0 1.0 1.0"/>
      </geometry>
    </collision>
  </link>
  <gazebo reference="gripper_active2_link">
    <material>Gazebo/White</material>
    <!--selfCollide>true</selfCollide-->
    <gravity>true</gravity>
  </gazebo>
  <!-- Using Mimic -->
  <!-- gripper 2 joint -->
  <!--  TODO: Test Mimic ->
    <joint name="gripper2_joint" type="prismatic">
      <origin xyz="0.070 0 0" rpy="0 0 0"/>
      <axis xyz="0 1 0"/>
      <limit effort="30" velocity="0.5" lower="-0.016" upper="-0.002"/>
      <parent link="arm_wrist_flex_link"/>
      <child link="gripper_active2_link"/>
      <mimic joint="gripper_joint" multiplier="-1"  offset = "0"/>
    </joint-->
  <!-- gripper_link -->
  <link name="gripper_link"/>
  <joint name="gripper_link_joint" type="revolute">
    <origin rpy="0 0 0" xyz="0.110 0 0"/>
    <parent link="arm_wrist_flex_link"/>
    <child link="gripper_link"/>
    <limit effort="6" lower="-3.14" upper="3.14" velocity="1"/>
    <axis xyz="1 0 0"/>
  </joint>
  <!--gazebo>
      <gripper name="gripper">
        <grasp_check>
          <attach_steps>5</attach_steps>
          <detach_steps>10</detach_steps>
          <min_contact_count>2</min_contact_count>
        </grasp_check>
      </gripper>
      <gripper_link>gripper_active_link</gripper_link>
      <palm_link>gripper_servo_link</palm_link>
  </gazebo-->
</robot>

